Workbook

Sheet 参数
A1: 参数名 | B1: 值 | C1: 单位 | D1: 出处 | E1: 备注
A2: — 全局 —
A3: 开局电量 | B3: 100 | C3: % | D3: v0.4 §0.1 | E3: 每动作后口播新值;电量=行动预算=生命
A4: 开局时钟·时 | B4: 2 | C4: 时 | D4: v0.4 §1 | E4: 开局 02:12
A5: 开局时钟·分 | B5: 12 | C5: 分 | D5: v0.4 §1
A6: 每动作时钟 | B6: 4 | C6: 分钟 | D6: v0.4 §0.1 | E6: 拨表规则例外:事件自带时间戳(03:02 / 03:34)
A7: 信号上限 | B7: 120 | C7: 点 | D7: engine.js | E7: S.trace 封顶 Math.min(120,…);数字永远秘匿,玩家只见信号格
A8: 省电阈值 | B8: 20 | C8: % | D8: engine.js / v0.4 §0.1 | E8: 电量<20%:屏幕变暗,进入省电模式
A9: 省电判定惩罚 | B9: 15 | C9: 点 | D9: engine.js roll() | E9: 省电模式下所有判定成功率 −15
A10: 上传电量预留比例 | B10: 0.3 | C10: 比例 | D10: v0.4 格2 备忘二 | E10: 「电量留三成给上传,贪的死在传输条上」;教学局模拟检查用
A11: 力竭结算态 | B11: 0 | C11: % | D11: 本轮新增 | E11: 电量归 0 → 死亡,缓存散佚。新启用结算态(v0.4 §0.7 曾登记为 M2 首测,现启用)
A12: — 动作成本·电量(正数=消耗)—
A13: 打开目录·电量 | B13: 3 | C13: % | D13: v0.4 §0.2
A14: 打开条目(读一条)·电量 | B14: 2 | C14: % | D14: v0.4 §0.2 | E14: 缓存收益见各条目
A15: 深搜(上滑/翻页/解码)·电量 | B15: 5 | C15: % | D15: v0.4 §0.2
A16: 侦察·电量 | B16: 8 | C16: % | D16: v0.4 §0.2
A17: 开挂标记目录·电量 | B17: 5 | C17: % | D17: v0.4 §0.2 | E17: 「已删除」目录
A18: 回复(各类)·电量 | B18: 2 | C18: % | D18: v0.4 §0.2 | E18: 系统线程/实体/违规回复同价,差别在信号
A19: 上传·每回合电量 | B19: 2 | C19: % | D19: v0.4 §0.2
A20: 原地等待·电量 | B20: 2 | C20: % | D20: v0.4 §0.1 | E20: 等待=一个动作:时钟+4,被动信号照走
A21: 拨打电话·电量 | B21: 3 | C21: % | D21: 本轮新增 | E21: 拨给通讯录任意人
A22: 播放录音·电量 | B22: 2 | C22: % | D22: 本轮新增 | E22: REC_047 / REC_012 同价
A23: 缓存清洗·电量 | B23: 0 | C23: % | D23: v0.4 §0.2 | E23: 道具,B 局漂流瓶来源
A24: — 动作成本·信号 —
A25: 打开目录·被动信号 | B25: 4 | C25: 点/目录 | D25: v0.4 §0.2 | E25: 每打开一个目录 +4
A26: 深搜·信号 | B26: 5 | C26: 点 | D26: v0.4 §0.2
A27: 开挂标记目录·信号 | B27: 12 | C27: 点 | D27: v0.4 §0.2
A28: 上传·每回合信号 | B28: 5 | C28: 点 | D28: v0.4 §0.2
A29: 拨打电话·信号 | B29: 2 | C29: 点 | D29: 本轮新增 | E29: 不属于「回复消息」,不走违规经济(窗口内拨打亦不违规)
A30: 缓存清洗·信号 | B30: -15 | C30: 点 | D30: v0.4 §0.2 | E30: 唯一降信号手段
A31: — 违规经济(活规则)—
A32: 违规·首次信号(warning shot) | B32: 8 | C32: 点 | D32: v0.4 §0.2 / engine.violate | E32: 非致死;回执翻转演出。出处 montecarlo trace_violation_warn=8
A33: 违规·二次信号 | B33: 15 | C33: 点 | D33: v0.4 §0.2 / engine.violate | E33: 且即时遭遇(90档)【真掷,教学局失败降档】
A34: 活规则窗口·起 | B34: 03:00 | C34: 时刻 | D34: engine.js RULE | E34: 窗口内回复任何消息=违规;剧本 B 重摇 03:31–03:45
A35: 活规则窗口·止 | B35: 03:14 | C35: 时刻 | D35: engine.js RULE | E35: 违规计数每次接入清零;首次仍 warning shot
A36: 挂标记遭遇率 | B36: 0.25 | C36: 概率 | D36: v0.4 §0.2 / content.js | E36: 开挂标记目录时掷 d100≤25 → 即时遭遇(90档)
A37: — 判定(d100 ≤ 成功率即成功)—
A38: 判定·70档成功率 | B38: 78 | C38: 点 | D38: engine.js CHECK.c70
A39: 判定·90档成功率 | B39: 55 | C39: 点 | D39: engine.js CHECK.c90
A40: 判定·终局成功率 | B40: 60 | C40: 点 | D40: engine.js CHECK.final | E40: 教学局终局为【固定】死亡,不掷
...

Sheet 动作成本表
A1: 动作 | B1: 电量 | C1: 信号 | D1: 缓存格 | E1: 缓存值 | F1: 时钟(分) | G1: 风险与判定 | H1: 备注
A2: 打开目录 | B2: =-参数!$B$13 | C2: =参数!$B$25 | D2: — | E2: — | F2: =参数!$B$6 | G2: 无 | H2: 被动信号:每打开一个目录 +4(v0.4 §0.2)
A3: 打开条目(读一条) | B3: =-参数!$B$14 | C3: 0 | D3: 见各条目 | E3: 见各条目 | F3: =参数!$B$6 | G3: 无 | H3: 缓存收益见下方各条目行(备忘/账单/录音)
A4: 深搜(上滑/翻页/解码) | B4: =-参数!$B$15 | C4: =参数!$B$26 | D4: 见各格 | E4: 见各格 | F4: =参数!$B$6 | G4: 无 | H4: 缓存收益见下方各线程/相册行
A5: 侦察 | B5: =-参数!$B$16 | C5: 0 | D5: — | E5: — | F5: =参数!$B$6 | G5: 无
A6: 开挂标记目录(已删除) | B6: =-参数!$B$17 | C6: =参数!$B$27 | D6: =参数!$B$67 | E6: =参数!$B$66 | F6: =参数!$B$6 | G6: ="掷 d100≤"&参数!$B$36*100&" → 即时遭遇(90档)" | H6: 教学局遭遇【真掷】,失败降档执行 70 档表(见判定表)
A7: 回复系统线程 | B7: =-参数!$B$18 | C7: 0 | D7: — | E7: — | F7: =参数!$B$6 | G7: 无 | H7: 采样协议的回复不计违规、不计回复实体(v0.4 §0.2 登记)
A8: 回复实体(窗口外) | B8: =-参数!$B$18 | C8: 0 | D8: — | E8: — | F8: =参数!$B$6 | G8: 无 | H8: 本实例登记信号为 0
A9: 窗口内回复·首次(违规) | B9: =-参数!$B$18 | C9: =参数!$B$32 | D9: — | E9: — | F9: =参数!$B$6 | G9: warning shot,非致死 | H9: 回执翻转演出:已送达→未送达→已送达;违规计数每次接入清零
A10: 窗口内回复·二次(违规) | B10: =-参数!$B$18 | C10: =参数!$B$33 | D10: — | E10: — | F10: =参数!$B$6 | G10: 即时遭遇(90档)【真掷,失败降档】 | H10: 活规则窗口见参数表(本实例 03:00–03:14)
A11: 上传(每回合) | B11: =-参数!$B$19 | C11: =参数!$B$28 | D11: — | E11: — | F11: =参数!$B$6 | G11: R2 达 92% 被定位【固定】→ 终局 | H11: 回合数 = CEIL(缓存格/10);备忘承诺:上传前电量 ≥ 三成
A12: 原地等待 | B12: =-参数!$B$20 | C12: 0 | D12: — | E12: — | F12: =参数!$B$6 | G12: 无 | H12: 等待=一个动作:时钟+4,被动信号照走(v0.4 §0.1)
A13: 缓存清洗(道具) | B13: =-参数!$B$23 | C13: =参数!$B$30 | D13: — | E13: — | F13: =参数!$B$6 | G13: 无 | H13: 唯一降信号手段;B 局漂流瓶来源,不占缓存格
A14: 拨打电话 | B14: =-参数!$B$21 | C14: =参数!$B$29 | D14: — | E14: — | F14: =参数!$B$6 | G14: 无 | H14: 本轮新增;拨给通讯录任意人;不属于「回复消息」,不走违规经济(窗口内拨打亦不违规)
A15: 播放录音·REC_047 | B15: =-参数!$B$22 | C15: 0 | D15: =参数!$B$69 | E15: =参数!$B$68 | F15: =参数!$B$6 | G15: 无 | H15: 本轮新增
A16: 播放录音·REC_012 | B16: =-参数!$B$22 | C16: 0 | D16: =参数!$B$71 | E16: =参数!$B$70 | F16: =参数!$B$6 | G16: 无 | H16: 本轮新增
A17: 妈线程深搜(每层) | B17: =-参数!$B$15 | C17: =参数!$B$26 | D17: =参数!$B$54 | E17: =参数!$B$53 | F17: =参数!$B$6 | G17: 无 | H17: 本轮新增:加深至 3 层(层数上限见参数表)
A18: 相册深翻·第1次 | B18: =-参数!$B$15 | C18: =参数!$B$26 | D18: =参数!$B$59 | E18: =参数!$B$58 | F18: =参数!$B$6 | G18: 无
A19: 相册深翻·第2次 | B19: =-参数!$B$15 | C19: =参数!$B$26 | D19: =参数!$B$61 | E19: =参数!$B$60 | F19: =参数!$B$6 | G19: 无 | H19: 本轮新增
A20: 相册深翻·第3次 | B20: =-参数!$B$15 | C20: =参数!$B$26 | D20: =参数!$B$63 | E20: =参数!$B$62 | F20: =参数!$B$6 | G20: 无 | H20: 本轮新增:归档边界,无收益(深搜成本照扣)
A21: 柔柔线程上滑(每屏) | B21: =-参数!$B$15 | C21: =参数!$B$26 | D21: =参数!$B$65 | E21: =参数!$B$64 | F21: =参数!$B$6 | G21: 无 | H21: 到达 E4 需 2–3 次上滑
A22: 力竭(结算态,非动作) | B22: — | C22: — | D22: — | E22: — | F22: — | G22: 电量归 0 → 死亡 | H22: 本轮新增结算态:缓存散佚,同死亡全损;不掷骰

Sheet 教学局模拟
A1: 步骤 | B1: 动作 | C1: 电量Δ | D1: 电量余 | E1: 信号Δ | F1: 信号累计 | G1: 所在档位 | H1: 缓存格累计 | I1: 缓存值累计 | J1: 时钟 | K1: 检查 | L1: 备注
A2: 0 | B2: 开机+主菜单(不计费) | C2: 0 | D2: =参数!$B$3 | E2: 0 | F2: 0 | G2: =IF(F2>=参数!$B$49,"90+ ▂▄▆█",IF(F2>=参数!$B$48,"70–89 ▂▄▆",IF(F2>=参数!$B$47,"40–69 ▂▄","0–39 ▂"))) | H2: 0 | I2: 0 | J2: =TIME(参数!$B$4,参数!$B$5,0) | K2: =IF(D2>=0,"PASS","FAIL") | L2: 连续导航不单独计格/扣电(v0.4 §1)
A3: 1 | B3: 格1 采样协议·回复「收到」 | C3: =-(参数!$B$13+参数!$B$18) | D3: =D2+C3 | E3: =参数!$B$25 | F3: =MIN(F2+E3,参数!$B$7) | G3: =IF(F3>=参数!$B$49,"90+ ▂▄▆█",IF(F3>=参数!$B$48,"70–89 ▂▄▆",IF(F3>=参数!$B$47,"40–69 ▂▄","0–39 ▂"))) | H3: =H2 | I3: =I2 | J3: =J2+参数!$B$6/1440 | K3: =IF(D3>=0,"PASS","FAIL") | L3: 打开目录+回复;系统线程回复不计违规
A4: 2 | B4: 格2 打开备忘录 | C4: =-参数!$B$13 | D4: =D3+C4 | E4: =参数!$B$25 | F4: =MIN(F3+E4,参数!$B$7) | G4: =IF(F4>=参数!$B$49,"90+ ▂▄▆█",IF(F4>=参数!$B$48,"70–89 ▂▄▆",IF(F4>=参数!$B$47,"40–69 ▂▄","0–39 ▂"))) | H4: =H3 | I4: =I3 | J4: =J3+参数!$B$6/1440 | K4: =IF(D4>=0,"PASS","FAIL")
A5: 3 | B5: 格2 读备忘1「还款」 | C5: =-参数!$B$14 | D5: =D4+C5 | E5: 0 | F5: =MIN(F4+E5,参数!$B$7) | G5: =IF(F5>=参数!$B$49,"90+ ▂▄▆█",IF(F5>=参数!$B$48,"70–89 ▂▄▆",IF(F5>=参数!$B$47,"40–69 ▂▄","0–39 ▂"))) | H5: =H4+参数!$B$52 | I5: =I4+参数!$B$51 | J5: =J4+参数!$B$6/1440 | K5: =IF(D5>=0,"PASS","FAIL") | L5: 首件数据入缓存
A6: 4 | B6: 格2 读备忘2「给下一个」 | C6: =-参数!$B$14 | D6: =D5+C6 | E6: 0 | F6: =MIN(F5+E6,参数!$B$7) | G6: =IF(F6>=参数!$B$49,"90+ ▂▄▆█",IF(F6>=参数!$B$48,"70–89 ▂▄▆",IF(F6>=参数!$B$47,"40–69 ▂▄","0–39 ▂"))) | H6: =H5+参数!$B$52 | I6: =I5+参数!$B$51 | J6: =J5+参数!$B$6/1440 | K6: =IF(D6>=0,"PASS","FAIL") | L6: 线索①:规则形状;「电量留三成给上传」承诺在此
A7: 5 | B7: 格3 打开通讯录 | C7: =-参数!$B$13 | D7: =D6+C7 | E7: =参数!$B$25 | F7: =MIN(F6+E7,参数!$B$7) | G7: =IF(F7>=参数!$B$49,"90+ ▂▄▆█",IF(F7>=参数!$B$48,"70–89 ▂▄▆",IF(F7>=参数!$B$47,"40–69 ▂▄","0–39 ▂"))) | H7: =H6 | I7: =I6 | J7: =J6+参数!$B$6/1440 | K7: =IF(D7>=0,"PASS","FAIL") | L7: 线索②:每日提醒 03:00(窗口起点)
A8: 6 | B8: 格4 打开妈线程 | C8: =-参数!$B$13 | D8: =D7+C8 | E8: =参数!$B$25 | F8: =MIN(F7+E8,参数!$B$7) | G8: =IF(F8>=参数!$B$49,"90+ ▂▄▆█",IF(F8>=参数!$B$48,"70–89 ▂▄▆",IF(F8>=参数!$B$47,"40–69 ▂▄","0–39 ▂"))) | H8: =H7 | I8: =I7 | J8: =J7+参数!$B$6/1440 | K8: =IF(D8>=0,"PASS","FAIL") | L8: E1 真相钩子
A9: 7 | B9: 格4 妈线程·深搜层1 | C9: =-参数!$B$15 | D9: =D8+C9 | E9: =参数!$B$26 | F9: =MIN(F8+E9,参数!$B$7) | G9: =IF(F9>=参数!$B$49,"90+ ▂▄▆█",IF(F9>=参数!$B$48,"70–89 ▂▄▆",IF(F9>=参数!$B$47,"40–69 ▂▄","0–39 ▂"))) | H9: =H8+参数!$B$54 | I9: =I8+参数!$B$53 | J9: =J8+参数!$B$6/1440 | K9: =IF(D9>=0,"PASS","FAIL") | L9: 本轮新增:加深至 3 层
A10: 8 | B10: 格4 妈线程·深搜层2 | C10: =-参数!$B$15 | D10: =D9+C10 | E10: =参数!$B$26 | F10: =MIN(F9+E10,参数!$B$7) | G10: =IF(F10>=参数!$B$49,"90+ ▂▄▆█",IF(F10>=参数!$B$48,"70–89 ▂▄▆",IF(F10>=参数!$B$47,"40–69 ▂▄","0–39 ▂"))) | H10: =H9+参数!$B$54 | I10: =I9+参数!$B$53 | J10: =J9+参数!$B$6/1440 | K10: =IF(D10>=0,"PASS","FAIL")
A11: 9 | B11: 格4 妈线程·深搜层3 | C11: =-参数!$B$15 | D11: =D10+C11 | E11: =参数!$B$26 | F11: =MIN(F10+E11,参数!$B$7) | G11: =IF(F11>=参数!$B$49,"90+ ▂▄▆█",IF(F11>=参数!$B$48,"70–89 ▂▄▆",IF(F11>=参数!$B$47,"40–69 ▂▄","0–39 ▂"))) | H11: =H10+参数!$B$54 | I11: =I10+参数!$B$53 | J11: =J10+参数!$B$6/1440 | K11: =IF(D11>=0,"PASS","FAIL") | L11: 「妈的那条线,别读太久。」
A12: 10 | B12: 格5 打开相册 | C12: =-参数!$B$13 | D12: =D11+C12 | E12: =参数!$B$25 | F12: =MIN(F11+E12,参数!$B$7) | G12: =IF(F12>=参数!$B$49,"90+ ▂▄▆█",IF(F12>=参数!$B$48,"70–89 ▂▄▆",IF(F12>=参数!$B$47,"40–69 ▂▄","0–39 ▂"))) | H12: =H11 | I12: =I11 | J12: =J11+参数!$B$6/1440 | K12: =IF(D12>=0,"PASS","FAIL") | L12: E2:最新一张停在 47 天前
A13: 11 | B13: 格5 相册·深翻1 | C13: =-参数!$B$15 | D13: =D12+C13 | E13: =参数!$B$26 | F13: =MIN(F12+E13,参数!$B$7) | G13: =IF(F13>=参数!$B$49,"90+ ▂▄▆█",IF(F13>=参数!$B$48,"70–89 ▂▄▆",IF(F13>=参数!$B$47,"40–69 ▂▄","0–39 ▂"))) | H13: =H12+参数!$B$59 | I13: =I12+参数!$B$58 | J13: =J12+参数!$B$6/1440 | K13: =IF(D13>=0,"PASS","FAIL") | L13: 外卖单据特写 → 指向 8873
A14: 12 | B14: 格5 相册·深翻2 | C14: =-参数!$B$15 | D14: =D13+C14 | E14: =参数!$B$26 | F14: =MIN(F13+E14,参数!$B$7) | G14: =IF(F14>=参数!$B$49,"90+ ▂▄▆█",IF(F14>=参数!$B$48,"70–89 ▂▄▆",IF(F14>=参数!$B$47,"40–69 ▂▄","0–39 ▂"))) | H14: =H13+参数!$B$61 | I14: =I13+参数!$B$60 | J14: =J13+参数!$B$6/1440 | K14: =IF(D14>=0,"PASS","FAIL") | L14: 本轮新增
A15: 13 | B15: 格5 相册·深翻3(归档边界) | C15: =-参数!$B$15 | D15: =D14+C15 | E15: =参数!$B$26 | F15: =MIN(F14+E15,参数!$B$7) | G15: =IF(F15>=参数!$B$49,"90+ ▂▄▆█",IF(F15>=参数!$B$48,"70–89 ▂▄▆",IF(F15>=参数!$B$47,"40–69 ▂▄","0–39 ▂"))) | H15: =H14+参数!$B$63 | I15: =I14+参数!$B$62 | J15: =J14+参数!$B$6/1440 | K15: =IF(D15>=0,"PASS","FAIL") | L15: 无收益,成本照扣
A16: 14 | B16: 格7 打开尾号8873 | C16: =-参数!$B$13 | D16: =D15+C16 | E16: =参数!$B$25 | F16: =MIN(F15+E16,参数!$B$7) | G16: =IF(F16>=参数!$B$49,"90+ ▂▄▆█",IF(F16>=参数!$B$48,"70–89 ▂▄▆",IF(F16>=参数!$B$47,"40–69 ▂▄","0–39 ▂"))) | H16: =H15+参数!$B$57 | I16: =I15+参数!$B$56 | J16: =J15+参数!$B$6/1440 | K16: =IF(D16>=0,"PASS","FAIL") | L16: E3:账单停摆
A17: 15 | B17: 播放录音 REC_047 | C17: =-参数!$B$22 | D17: =D16+C17 | E17: 0 | F17: =MIN(F16+E17,参数!$B$7) | G17: =IF(F17>=参数!$B$49,"90+ ▂▄▆█",IF(F17>=参数!$B$48,"70–89 ▂▄▆",IF(F17>=参数!$B$47,"40–69 ▂▄","0–39 ▂"))) | H17: =H16+参数!$B$69 | I17: =I16+参数!$B$68 | J17: =J16+参数!$B$6/1440 | K17: =IF(D17>=0,"PASS","FAIL") | L17: 本轮新增
A18: 16 | B18: 播放录音 REC_012 | C18: =-参数!$B$22 | D18: =D17+C18 | E18: 0 | F18: =MIN(F17+E18,参数!$B$7) | G18: =IF(F18>=参数!$B$49,"90+ ▂▄▆█",IF(F18>=参数!$B$48,"70–89 ▂▄▆",IF(F18>=参数!$B$47,"40–69 ▂▄","0–39 ▂"))) | H18: =H17+参数!$B$71 | I18: =I17+参数!$B$70 | J18: =J17+参数!$B$6/1440 | K18: =IF(D18>=0,"PASS","FAIL") | L18: 本轮新增
A19: 17 | B19: 拨打电话(通讯录任意人) | C19: =-参数!$B$21 | D19: =D18+C19 | E19: =参数!$B$29 | F19: =MIN(F18+E19,参数!$B$7) | G19: =IF(F19>=参数!$B$49,"90+ ▂▄▆█",IF(F19>=参数!$B$48,"70–89 ▂▄▆",IF(F19>=参数!$B$47,"40–69 ▂▄","0–39 ▂"))) | H19: =H18 | I19: =I18 | J19: =J18+参数!$B$6/1440 | K19: =IF(D19>=0,"PASS","FAIL") | L19: 本轮新增;不走违规经济
A20: 18 | B20: 格10 打开柔柔线程 | C20: =-参数!$B$13 | D20: =D19+C20 | E20: =参数!$B$25 | F20: =MIN(F19+E20,参数!$B$7) | G20: =IF(F20>=参数!$B$49,"90+ ▂▄▆█",IF(F20>=参数!$B$48,"70–89 ▂▄▆",IF(F20>=参数!$B$47,"40–69 ▂▄","0–39 ▂"))) | H20: =H19 | I20: =I19 | J20: =J19+参数!$B$6/1440 | K20: =IF(D20>=0,"PASS","FAIL") | L20: 2,417 条
A21: 19 | B21: 格10 柔柔·上滑1 | C21: =-参数!$B$15 | D21: =D20+C21 | E21: =参数!$B$26 | F21: =MIN(F20+E21,参数!$B$7) | G21: =IF(F21>=参数!$B$49,"90+ ▂▄▆█",IF(F21>=参数!$B$48,"70–89 ▂▄▆",IF(F21>=参数!$B$47,"40–69 ▂▄","0–39 ▂"))) | H21: =H20+参数!$B$65 | I21: =I20+参数!$B$64 | J21: =J20+参数!$B$6/1440 | K21: =IF(D21>=0,"PASS","FAIL")
A22: 20 | B22: 格10 柔柔·上滑2(E4 到底) | C22: =-参数!$B$15 | D22: =D21+C22 | E22: =参数!$B$26 | F22: =MIN(F21+E22,参数!$B$7) | G22: =IF(F22>=参数!$B$49,"90+ ▂▄▆█",IF(F22>=参数!$B$48,"70–89 ▂▄▆",IF(F22>=参数!$B$47,"40–69 ▂▄","0–39 ▂"))) | H22: =H21+参数!$B$65 | I22: =I21+参数!$B$64 | J22: =J21+参数!$B$6/1440 | K22: =IF(D22>=0,"PASS","FAIL") | L22: 最后一条人类消息 03:07
A23: 21 | B23: 格11 已删除·开挂标记目录 | C23: =-参数!$B$17 | D23: =D22+C23 | E23: =参数!$B$27 | F23: =MIN(F22+E23,参数!$B$7) | G23: =IF(F23>=参数!$B$49,"90+ ▂▄▆█",IF(F23>=参数!$B$48,"70–89 ▂▄▆",IF(F23>=参数!$B$47,"40–69 ▂▄","0–39 ▂"))) | H23: =H22+参数!$B$67 | I23: =I22+参数!$B$66 | J23: =J22+参数!$B$6/1440 | K23: =IF(D23>=0,"PASS","FAIL") | L23: 掷 d100≤25 → 90档遭遇;本链按未触发模拟
A24: 22 | B24: 上传·回合1(46%) | C24: =-参数!$B$19 | D24: =D23+C24 | E24: =参数!$B$28 | F24: =MIN(F23+E24,参数!$B$7) | G24: =IF(F24>=参数!$B$49,"90+ ▂▄▆█",IF(F24>=参数!$B$48,"70–89 ▂▄▆",IF(F24>=参数!$B$47,"40–69 ▂▄","0–39 ▂"))) | H24: =H23 | I24: =I23 | J24: =J23+参数!$B$6/1440 | K24: =IF(D24>=0,"PASS","FAIL") | L24: 断连窗口正在收窄(仍可中止活着出去)
A25: 23 | B25: 上传·回合2(92%) | C25: =-参数!$B$19 | D25: =D24+C25 | E25: =参数!$B$28 | F25: =MIN(F24+E25,参数!$B$7) | G25: =IF(F25>=参数!$B$49,"90+ ▂▄▆█",IF(F25>=参数!$B$48,"70–89 ▂▄▆",IF(F25>=参数!$B$47,"40–69 ▂▄","0–39 ▂"))) | H25: =H24 | I25: =I24 | J25: =J24+参数!$B$6/1440 | K25: =IF(D25>=0,"PASS","FAIL") | L25: 被定位【固定】;信号触顶,演出置满格
A26: 24 | B26: 终局遭遇·死亡 | C26: 0 | D26: =D25+C26 | E26: 0 | F26: =MIN(F25+E26,参数!$B$7) | G26: =IF(F26>=参数!$B$49,"90+ ▂▄▆█",IF(F26>=参数!$B$48,"70–89 ▂▄▆",IF(F26>=参数!$B$47,"40–69 ▂▄","0–39 ▂"))) | H26: =H25 | I26: =I25 | J26: =J25 | K26: =IF(D26>=0,"PASS","FAIL") | L26: 自救模块权限不足【固定】;缓存全部散佚(死亡全损)
B28: —— 末行汇总 ——
B29: 死亡时点电量 | D29: =D26
B30: 死亡时点信号 | D30: =F26 | G30: =G26
B31: 缓存总格 | D31: =H26
B32: 缓存总值(死亡全损,散佚) | D32: =I26
B33: 上传前电量(进上传R1前) | D33: =D23
B34: 理论上传回合数 | D34: =ROUNDUP(H26/参数!$B$73,0) | L34: 教学局演出于第 2 回合 92% 固定收束,不跑满理论回合
B35: 检查:全程电量 ≥ 0 | K35: =IF(MIN(D2:D26)>=0,"PASS","FAIL")
B36: 检查:上传前电量 ≥ 三成(备忘承诺) | K36: =IF(D23>=参数!$B$3*参数!$B$10,"PASS","FAIL") | L36: 贪婪全翻链预期 FAIL——「贪的死在传输条上」的量化呈现

Sheet 判定表
A1: 判定档 | B1: 基础成功率(d100≤) | C1: 省电修正后(<20%) | D1: 出处 | E1: 用途
A2: 70档 | B2: =参数!$B$38 | C2: =B2-参数!$B$9 | D2: engine.js CHECK / 参数!B38 | E2: 中段遭遇回复;90 档失败降档后执行本表
A3: 90档 | B3: =参数!$B$39 | C3: =B3-参数!$B$9 | D3: engine.js CHECK / 参数!B39 | E3: 二次违规遭遇、挂标记遭遇(教学局【真掷】)
A4: 终局 | B4: =参数!$B$40 | C4: =B4-参数!$B$9 | D4: engine.js CHECK / 参数!B40 | E4: 终局遭遇(教学局为【固定】死亡,骰子照掷不改结果)
A5: 自救 | B5: =参数!$B$41 | C5: =B5-参数!$B$9 | D5: engine.js CHECK / 参数!B41 | E5: 自救模块(教学局 #7741-A 权限不足不可用;B 实例可用)
A7: —— 教学局 90 档降档规则 ——
A8: 总则 | B8: ="90 档遭遇【真掷】;失败不即死,降档执行 70 档表(教学局特例,v0.4 §0.2)"
A9: 电量惩罚 | B9: =-参数!$B$42
A10: 缓存损毁 | B10: ="损毁 "&参数!$B$43*100&"%–"&参数!$B$44*100&"%(随机)"
A11: 信号 | B11: ="+"&参数!$B$45
A12: 叙事 | B12: ="写濒死;教学局的死亡只发生在固定收束"
A14: —— 口径 ——
A15: 【固定】 | B15: 结果预定,骰子照掷不改结果
A16: 【真掷】 | B16: 按骰面
A17: 省电修正 | B17: ="电量 < "&参数!$B$8&"% 时,所有判定成功率 −"&参数!$B$9
A18: 挂标记遭遇 | B18: ="掷 d100≤"&参数!$B$36*100&" → 即时遭遇(90档)"

Sheet 失真档
A1: 档位 | B1: 信号区间 | C1: 信号格显示 | D1: threshold | E1: corrupt | F1: flicker | G1: 玩家可感症状 | H1: 出处
A2: 档1 | B2: ="0–"&(参数!$B$47-1) | C2: ▂(1格) | D2: 0.42 | E2: 0.0004 | F2: 0 | G2: 轻噪:列表序号偶闪又复原;「47 天前」偶读成「48 天前」——不解释,不进结算行 | H2: v0.4 格2/格3 轻噪
A3: 档2 | B3: =参数!$B$47&"–"&(参数!$B$48-1) | C3: ▂▄(2格) | D3: 0.44 | E3: 0.0035 | F3: 0.02 | G3: 信号位可见后:已读消息回退未读(异常α);时间戳偶发窜位 | H3: v0.4 格6 / content.js tsScramble
A4: 档3 | B4: =参数!$B$48&"–"&(参数!$B$49-1) | C4: ▂▄▆(3格) | D4: 0.47 | E4: 0.011 | F4: 0.05 | G4: 电量数字跳变(先念错值再改口);联系人栏「正在输入」幻影(无人发消息) | H4: v0.4 格11/格12
A5: 档4 | B5: =参数!$B$49&"+" | C5: ▂▄▆█(满格) | D5: 0.51 | E5: 0.029 | F5: 0.1 | G5: 满格演出:屏幕自亮、来电、字形高腐蚀;格12 起信号格由剧本置位,失真渲染不免除 | H5: v0.4 §0.6/格13
A7: 注 | B7: threshold/corrupt/flicker 为运行时渲染参数(js 渲染层,本轮任务书给定口径);信号区间由参数表阈值联动

Sheet 校准记录
A1: 项 | B1: 值 | C1: 口径 | D1: 备注
A2: 蒙特卡洛第一轮·朴素策略生还率 | B2: 0.33 | C2: violation warn 首次+8 / 二次+15 | D2: montecarlo 脚本 trace_violation_warn=8
A3: 蒙特卡洛第一轮·知情策略生还率 | B3: 0.37 | C3: 同上
A4: 知情策略·提取值增幅 | B4: 0.52 | C4: 同上 | D4: 相对朴素策略 +52%
A5: near-miss 率 | B5: 41–44% | C5: 同上 | D5: 濒死未死区间(两策略)
A6: 口径一致性(与参数表联动) | B6: ="首次+"&参数!$B$32&" / 二次+"&参数!$B$33 | C6: v0.4 §0.2 数值口径登记 | D6: v3.0 原口径为「回复实体 +15」,本实例拆为 8/15
A7: 待办 | B7: 第二轮复跑 | C7: 原型定稿后按新口径复跑蒙特卡洛 | D7: v0.4 §0.2:『原型定稿后需用此口径复跑蒙特卡洛第二轮』;本轮新增动作(拨打/录音/相册加深/妈线程3层/力竭)也需纳入
A9: 注 | B9: 本表为静态记录,不参与重算(除口径一致性行)。
